Workbook

Sheet README
A1: Bulk-fuel inventory corrections — manual review
A3: What this is: 104 candidate corrections to the AEA Utilities_Bulk_Fuel_Inventory.csv (2022 file, SHA-256 132338fe…). Nothing is applied until mannually approved.
A4: Tabs 1–7 hold one correction type each. Tab 'Summary' counts your decisions (formulas update as you fill in).
A6: Cells to edit — yellow columns only:
A7: decision choose from the dropdown: approve | approve with my value | reject | ask AEA | skip for now
A8: your_value only if 'approve with my value': the value you want instead (lat,lon or a community name)
A9: notes what you checked (e.g. 'Google satellite: tank farm visible at proposed point')
A10: reviewed_by / reviewed_on your initials and date
A12: Example of a filled-in row (format only, not real): decision = approve with my value · your_value = 60.79210,-161.75890 · notes = 'tank farm on satellite 300 m from proposal' · reviewed_by = JC · reviewed_on = 2026-10-06
A14: How to check a row:
A15: 1. Click 'map: stored' and 'map: proposed' (open Google Maps at each point; nothing is sent until you click).
A16: 2. Look for the tank farm / community at the proposed point; compare with the label.
... A22: Privacy: built from id, location, community, delivery-method and capacity columns only — no contact fields.

Sheet Summary
A1: Group | B1: Rows | C1: approve | D1: approve with my value | E1: reject | F1: ask AEA | G1: skip for now | H1: Not yet decided
A2: 1 Coordinate typos | B2: =COUNTA('1 Coordinate typos'!A2:A5) -> 4 | C2: =COUNTIF('1 Coordinate typos'!T2:T5,"approve") -> 4 | D2: =COUNTIF('1 Coordinate typos'!T2:T5,"approve with my value") -> 0 | E2: =COUNTIF('1 Coordinate typos'!T2:T5,"reject") -> 0 | F2: =COUNTIF('1 Coordinate typos'!T2:T5,"ask AEA") -> 0 | G2: =COUNTIF('1 Coordinate typos'!T2:T5,"skip for now") -> 0 | H2: =B2-SUM(C2:G2) -> 0
A3: 2 Possible typos | B3: =COUNTA('2 Possible typos'!A2:A5) -> 4 | C3: =COUNTIF('2 Possible typos'!T2:T5,"approve") -> 0 | D3: =COUNTIF('2 Possible typos'!T2:T5,"approve with my value") -> 0 | E3: =COUNTIF('2 Possible typos'!T2:T5,"reject") -> 4 | F3: =COUNTIF('2 Possible typos'!T2:T5,"ask AEA") -> 0 | G3: =COUNTIF('2 Possible typos'!T2:T5,"skip for now") -> 0 | H3: =B3-SUM(C3:G3) -> 0
A4: 3 Swapped coords | B4: =COUNTA('3 Swapped coords'!A2:A3) -> 2 | C4: =COUNTIF('3 Swapped coords'!T2:T3,"approve") -> 2 | D4: =COUNTIF('3 Swapped coords'!T2:T3,"approve with my value") -> 0 | E4: =COUNTIF('3 Swapped coords'!T2:T3,"reject") -> 0 | F4: =COUNTIF('3 Swapped coords'!T2:T3,"ask AEA") -> 0 | G4: =COUNTIF('3 Swapped coords'!T2:T3,"skip for now") -> 0 | H4: =B4-SUM(C4:G4) -> 0
A5: 4 Wrong label | B5: =COUNTA('4 Wrong label'!A2:A10) -> 9 | C5: =COUNTIF('4 Wrong label'!T2:T10,"approve") -> 5 | D5: =COUNTIF('4 Wrong label'!T2:T10,"approve with my value") -> 0 | E5: =COUNTIF('4 Wrong label'!T2:T10,"reject") -> 1 | F5: =COUNTIF('4 Wrong label'!T2:T10,"ask AEA") -> 0 | G5: =COUNTIF('4 Wrong label'!T2:T10,"skip for now") -> 0 | H5: =B5-SUM(C5:G5) -> 3
A6: 5 Copied coords | B6: =COUNTA('5 Copied coords'!A2:A5) -> 4 | C6: =COUNTIF('5 Copied coords'!T2:T5,"approve") -> 0 | D6: =COUNTIF('5 Copied coords'!T2:T5,"approve with my value") -> 2 | E6: =COUNTIF('5 Copied coords'!T2:T5,"reject") -> 1 | F6: =COUNTIF('5 Copied coords'!T2:T5,"ask AEA") -> 0 | G6: =COUNTIF('5 Copied coords'!T2:T5,"skip for now") -> 0 | H6: =B6-SUM(C6:G6) -> 1
A7: 6 Shared-point stacks | B7: =COUNTA('6 Shared-point stacks'!A2:A52) -> 51 | C7: =COUNTIF('6 Shared-point stacks'!T2:T52,"approve") -> 0 | D7: =COUNTIF('6 Shared-point stacks'!T2:T52,"approve with my value") -> 0 | E7: =COUNTIF('6 Shared-point stacks'!T2:T52,"reject") -> 0 | F7: =COUNTIF('6 Shared-point stacks'!T2:T52,"ask AEA") -> 0 | G7: =COUNTIF('6 Shared-point stacks'!T2:T52,"skip for now") -> 0 | H7: =B7-SUM(C7:G7) -> 51
A8: 7 Spelling variants | B8: =COUNTA('7 Spelling variants'!A2:A31) -> 30 | C8: =COUNTIF('7 Spelling variants'!T2:T31,"approve") -> 30 | D8: =COUNTIF('7 Spelling variants'!T2:T31,"approve with my value") -> 0 | E8: =COUNTIF('7 Spelling variants'!T2:T31,"reject") -> 0 | F8: =COUNTIF('7 Spelling variants'!T2:T31,"ask AEA") -> 0 | G8: =COUNTIF('7 Spelling variants'!T2:T31,"skip for now") -> 0 | H8: =B8-SUM(C8:G8) -> 0
A9: Total | B9: =SUM(B2:B8) -> 104 | C9: =SUM(C2:C8) -> 41 | D9: =SUM(D2:D8) -> 2 | E9: =SUM(E2:E8) -> 6 | F9: =SUM(F2:F8) -> 0 | G9: =SUM(G2:G8) -> 0 | H9: =SUM(H2:H8) -> 55

Sheet 1 Coordinate typos
A1: facility_pid | B1: facility_id | C1: csv_row | D1: GlobalID | E1: label | F1: field | G1: current_lat | H1: current_lon | I1: proposed_lat | J1: proposed_lon | K1: current_value | L1: proposed_value | M1: confidence | N1: evidence | O1: aea_2025_status | P1: aea_2025_map_lat | Q1: aea_2025_map_lon | R1: map: stored | S1: map: proposed | T1: decision | U1: your_value | V1: notes | W1: reviewed_by | X1: reviewed_on
A2: f000120 | B2: 239 | C2: 1011 | D2: {5AEE4579-120C-418C-965A-911EFB7A4873} | E2: Kodiak | F2: latitude | G2: 54.853056 | H2: -152.39288 | I2: 57.79468 | J2: -152.39288 | K2: 54.853056 | L2: 57.79468 | M2: high | N2: AEA feature geometry (X/Y) puts the site at 57.79468,-152.39286 (Kodiak city); lat column 54.85306 is 328 km off. Builds a hub/position in open Pacific. | O2: unchanged | P2: 57.79468 | Q2: -152.39288 | R2: =HYPERLINK("https://www.google.com/maps?q=54.853056,-152.392880","map: stored") -> map: stored | S2: =HYPERLINK("https://www.google.com/maps?q=57.794680,-152.392880","map: proposed") -> map: proposed | T2: approve | V2: Address verified on AEA raw Bulk fuel facilitiy CSV | W2: JC | X2: 46300
A3: f000268 | B3: 772 | C3: 457 | D3: {D0D325AD-A296-437B-9213-8A2FD2F3621D} | E3: Coldfoot | F3: longitude;latitude | G3: 67.252778 | H3: -131.69972 | I3: 67.27808 | J3: -150.26877 | K3: 67.252778,-131.699722 | L3: 67.27808,-150.26877 | M3: high | N3: AEA feature geometry gives -150.26877 (Coldfoot); lon column -131.69972 is in Yukon, Canada, 803 km away; site lies outside every AEA region. First audit missed it (single-site cluster). | O3: unchanged | P3: 67.27808 | Q3: -150.2688 | R3: =HYPERLINK("https://www.google.com/maps?q=67.252778,-131.699722","map: stored") -> map: stored | S3: =HYPERLINK("https://www.google.com/maps?q=67.278080,-150.268770","map: proposed") -> map: proposed | T3: approve | V3: Confirmed via satelitte imagery on google maps | W3: JC | X3: 46301
A4: f000283 | B4: 600 | C4: 313 | D4: {8D408F52-5CE0-4A95-A586-79D54041D7C7} | E4: Bethel | F4: latitude | G4: 67.79558 | H4: -161.7611 | I4: 60.79558 | J4: -161.7611 | K4: 67.79558 | L4: 60.79558 | M4: high | N4: One-digit edit 67→60 lands in Bethel (60.79,-161.76); stored point is north of the Arctic Circle. Alone forms Hub_308 (h000054), not in the giant component. | O4: unchanged | P4: 67.79572 | Q4: -161.76111 | R4: =HYPERLINK("https://www.google.com/maps?q=67.795580,-161.761100","map: stored") -> map: stored | S4: =HYPERLINK("https://www.google.com/maps?q=60.795580,-161.761100","map: proposed") -> map: proposed | T4: approve | V4: Confirmed via satellite imagery & address on raw AEA bulk fuel facility CSV | W4: JC | X4: 46302
A5: f000093 | B5: 407 | C5: 1206 | D5: {978F2CF3-F873-42E9-A4F4-4744D455FBA9} | E5: New Stuyahok | F5: longitude | G5: 59.4571 | H5: -159.3748 | I5: 59.4571 | J5: -157.3748 | K5: -159.3748 | L5: -157.3748 | M5: high | N5: One-digit edit -159→-157 lands in New Stuyahok (59.45,-157.31); stored point is ~110 km west. | O5: unchanged | P5: 59.45709 | Q5: -159.37482 | R5: =HYPERLINK("https://www.google.com/maps?q=59.457100,-159.374800","map: stored") -> map: stored | S5: =HYPERLINK("https://www.google.com/maps?q=59.457100,-157.374800","map: proposed") -> map: proposed | T5: approve | V5: Places it at airport | W5: JC | X5: 46303

Sheet 2 Possible typos
A1: facility_pid | B1: facility_id | C1: csv_row | D1: GlobalID | E1: label | F1: field | G1: current_lat | H1: current_lon | I1: proposed_lat | J1: proposed_lon | K1: current_value | L1: proposed_value | M1: confidence | N1: evidence | O1: aea_2025_status | P1: aea_2025_map_lat | Q1: aea_2025_map_lon | R1: map: stored | S1: map: proposed | T1: decision | U1: your_value | V1: notes | W1: reviewed_by | X1: reviewed_on
A2: f000917 | B2: 1197 | C2: 507 | D2: {E4CF3B9E-8613-49C3-94A8-E46B9248AE34} | E2: Delta Junction | F2: longitude | G2: 63.999927 | H2: -144.73109 | I2: 63.999927 | J2: -145.73109 | K2: -144.731094 | L2: -145.731094 | M2: medium | N2: Delta Junction is at -145.73; stored -144.73 is ~50 km east. f001773 'Healy' sits on the same erroneous spot (copied). AEA geometry agrees with the stored value, so verify with AEA. | O2: unchanged | P2: 63.99988 | Q2: -144.73108 | R2: =HYPERLINK("https://www.google.com/maps?q=63.999927,-144.731094","map: stored") -> map: stored | S2: =HYPERLINK("https://www.google.com/maps?q=63.999927,-145.731094","map: proposed") -> map: proposed | T2: reject | U2: Label = 'Healy Lake' | V2: This tank belongs to Healy Lake, not Delta Junction. Confirmed with satellite imagery | W2: JC | X2: 46300
A3: f000228 | B3: 815 | C3: 1365 | D3: {0F01BB32-5A29-4652-976C-10E724180102} | E3: Petersburg | F3: latitude | G3: 56.236042 | H3: -132.98143 | I3: 56.736042 | J3: -132.98143 | K3: 56.236042 | L3: 56.736042 | M3: medium | N3: Petersburg area; stored 56.236 is ~55 km south in open water/Kupreanof south; candidate 56.736 is ~8 km from town. AEA geometry agrees with the stored value, so verify with AEA. | O3: unchanged | P3: 56.23608 | Q3: -132.98138 | R3: =HYPERLINK("https://www.google.com/maps?q=56.236042,-132.981428","map: stored") -> map: stored | S3: =HYPERLINK("https://www.google.com/maps?q=56.736042,-132.981428","map: proposed") -> map: proposed | T3: reject | V3: This tank can be grouped with the community label it is given. It is an AT&T facility that is confirmed via Google Maps satellite imagery, but the tank is located about 55km south of Petersburg | W3: JC | X3: 46300
A4: f000486 | B4: 452 | C4: 1369 | D4: {32574618-B703-4A8E-85F9-35EC4E4EA4A9} | E4: Pilot Point | F4: longitude | G4: 57.578333 | H4: -157.05389 | I4: 57.578333 | J4: -157.45389 | K4: -157.053889 | L4: -157.453889 | M4: medium | N4: Pilot Point is at -157.58; stored -157.054 is ~30 km east; candidate is ~8 km. AEA geometry agrees with the stored value, so verify with AEA. | O4: unchanged | P4: 57.57831 | Q4: -157.05389 | R4: =HYPERLINK("https://www.google.com/maps?q=57.578333,-157.053889","map: stored") -> map: stored | S4: =HYPERLINK("https://www.google.com/maps?q=57.578333,-157.453889","map: proposed") -> map: proposed | T4: reject | V4: Unclear if this needs to move, but this is another AT&T facility | W4: JC | X4: 46300
A5: f000386 | B5: 622 | C5: 1833 | D5: {78CFC821-3DC6-4967-BE1E-BF74D043A62F} | E5: Wrangell | F5: latitude | G5: 56.136278 | H5: -132.40492 | I5: 56.436278 | J5: -132.40492 | K5: 56.136278 | L5: 56.436278 | M5: medium | N5: Wrangell is at 56.47; stored 56.136 is ~35 km south; candidate within ~4 km. AEA geometry agrees with the stored value, so verify with AEA. | O5: unchanged | P5: 56.13629 | Q5: -132.40491 | R5: =HYPERLINK("https://www.google.com/maps?q=56.136278,-132.404917","map: stored") -> map: stored | S5: =HYPERLINK("https://www.google.com/maps?q=56.436278,-132.404917","map: proposed") -> map: proposed | T5: reject | V5: This is in the correct spot, confirmed by satellite imagery | W5: JC | X5: 46300

Sheet 3 Swapped coords
A1: facility_pid | B1: facility_id | C1: csv_row | D1: GlobalID | E1: label | F1: field | G1: current_lat | H1: current_lon | I1: proposed_lat | J1: proposed_lon | K1: current_value | L1: proposed_value | M1: confidence | N1: evidence | O1: aea_2025_status | P1: aea_2025_map_lat | Q1: aea_2025_map_lon | R1: map: stored | S1: map: proposed | T1: decision | U1: your_value | V1: notes | W1: reviewed_by | X1: reviewed_on
A2: f001606 | B2: 1096 | C2: 1770 | D2: {A5E8D42A-4A72-4380-B9D4-5CC0084B55D2} | E2: Unalaska | F2: latitude;longitude | G2: 63.89194 | H2: -160.6842 | I2: 53.88274 | J2: -166.55074 | K2: 63.89194,-160.6842 | L2: 53.88274,-166.550742 | M2: medium-high | N2: Coordinates swapped with f000147: this 'Unalaska' record sits in Unalakleet (15/15 neighbours Unalakleet) and f000147 'Unalakleet' sits in Dutch Harbor. CommunityID matches the label on both, so the positions are the swapped field. Alone creates Hub_62 (h000216) 'Unalaska' on Norton Sound. | O2: unchanged | P2: 63.89209 | Q2: -160.6842 | R2: =HYPERLINK("https://www.google.com/maps?q=63.891940,-160.684200","map: stored") -> map: stored | S2: =HYPERLINK("https://www.google.com/maps?q=53.882740,-166.550742","map: proposed") -> map: proposed | T2: approve | V2: confirmed on AEA raw bulk fuel facility CSV | W2: JC | X2: 46300
A3: f000147 | B3: 1255 | C3: 1756 | D3: {621FCC2F-3A90-426E-A211-00250864F71E} | E3: Unalakleet | F3: latitude;longitude | G3: 53.88274 | H3: -166.55074 | I3: 63.89194 | J3: -160.6842 | K3: 53.88274,-166.550742 | L3: 63.89194,-160.6842 | M3: medium-high | N3: Pair of f001606 (see there). In the build it is dropped as a cross-borough conflict (tag.assign_community_region). | O3: unchanged | P3: 53.88287 | Q3: -166.55072 | R3: =HYPERLINK("https://www.google.com/maps?q=53.882740,-166.550742","map: stored") -> map: stored | S3: =HYPERLINK("https://www.google.com/maps?q=63.891940,-160.684200","map: proposed") -> map: proposed | T3: approve | V3: confirmed on AEA raw bulk fuel facility CSV | W3: JC | X3: 46300

Sheet 4 Wrong label
A1: facility_pid | B1: facility_id | C1: csv_row | D1: GlobalID | E1: label | F1: field | G1: current_lat | H1: current_lon | I1: proposed_lat | J1: proposed_lon | K1: current_value | L1: proposed_value | M1: confidence | N1: evidence | O1: aea_2025_status | P1: aea_2025_map_lat | Q1: aea_2025_map_lon | R1: map: stored | S1: map: proposed | T1: decision | U1: your_value | V1: notes | W1: reviewed_by | X1: reviewed_on
A2: f000534 | B2: 1418 | C2: 481 | D2: {5CE97A73-0D33-4600-836B-A3E084CE3826} | E2: Craig | F2: community_name | G2: 56.017179 | H2: -132.82804 | K2: Craig | L2: Coffman Cove | M2: medium | N2: Independent point (0.3 km from the nearest other-community site); 5 of 5 sites within 15 km are 'Coffman Cove'. Label probably names the operator's home community, not the site. | O2: unchanged | P2: 56.01727 | Q2: -132.828 | R2: =HYPERLINK("https://www.google.com/maps?q=56.017179,-132.828041","map: stored") -> map: stored | S2: (label change) | V2: The supporting detials in the raw CSV value support the facility being located in Craig. It is just the coordinates that are placed in Coffman Cove | W2: JC | X2: 46300
A3: f000508 | B3: 51 | C3: 552 | D3: {B15A52C6-6F30-470D-9BA8-5037E9F1F1EC} | E3: Eielson Afb | F3: community_name | G3: 61.245907 | H3: -149.71069 | K3: Eielson Afb | L3: Anchorage | M3: medium | N3: Independent point (1.9 km from the nearest other-community site); 40 of 45 sites within 15 km are 'Anchorage'. Label probably names the operator's home community, not the site. | O3: unchanged | P3: 61.24591 | Q3: -149.71069 | R3: =HYPERLINK("https://www.google.com/maps?q=61.245907,-149.710691","map: stored") -> map: stored | S3: (label change) | T3: approve | V3: Located on JBER and labeled as JBER on raw CSV table | W3: JC | X3: 46300
A4: f001192 | B4: 754 | C4: 607 | D4: {BFC59C95-ABE4-4959-BE52-7F09A5308991} | E4: Fairbanks | F4: community_name | G4: 66.563958 | H4: -145.25879 | K4: Fairbanks | L4: Fort Yukon | M4: medium | N4: Independent point (0.1 km from the nearest other-community site); 20 of 22 sites within 15 km are 'Fort Yukon'. Label probably names the operator's home community, not the site. | O4: unchanged | P4: 66.56409 | Q4: -145.25879 | R4: =HYPERLINK("https://www.google.com/maps?q=66.563958,-145.258792","map: stored") -> map: stored | S4: (label change) | T4: approve | V4: Located in Fort Yukon. The University of Alaska Fairbanks most likely caused the switch | W4: JC | X4: 46300
A5: f000531 | B5: 1058 | C5: 626 | D5: {2B48564F-DF5A-4814-B2B3-21E3157048CA} | E5: Fairbanks | F5: community_name | G5: 64.51252 | H5: -165.4303 | K5: Fairbanks | L5: Nome | M5: medium | N5: Independent point (0.3 km from the nearest other-community site); 17 of 18 sites within 15 km are 'Nome'. Label probably names the operator's home community, not the site. | O5: unchanged | P5: 64.51251 | Q5: -165.4303 | R5: =HYPERLINK("https://www.google.com/maps?q=64.512520,-165.430300","map: stored") -> map: stored | S5: (label change) | W5: JC | X5: 46300
A6: f001218 | B6: 1060 | C6: 628 | D6: {9D56DBE7-1A09-4398-8622-73AF3113418C} | E6: Fairbanks | F6: community_name | G6: 64.51252 | H6: -165.4303 | K6: Fairbanks | L6: Nome | M6: medium | N6: Independent point (0.3 km from the nearest other-community site); 17 of 18 sites within 15 km are 'Nome'. Label probably names the operator's home community, not the site. | O6: unchanged | P6: 64.51251 | Q6: -165.4303 | R6: =HYPERLINK("https://www.google.com/maps?q=64.512520,-165.430300","map: stored") -> map: stored | S6: (label change) | W6: JC | X6: 46300
A7: f000732 | B7: 104 | C7: 649 | D7: {BDC6AEBD-A6BF-4D0C-929B-36D15018837C} | E7: Fort Wainwright | F7: community_name | G7: 60.132528 | H7: -149.433 | K7: Fort Wainwright | L7: Seward | M7: medium | N7: Independent point (0.2 km from the nearest other-community site); 12 of 12 sites within 15 km are 'Seward'. Label probably names the operator's home community, not the site. | O7: unchanged | P7: 60.13251 | Q7: -149.43298 | R7: =HYPERLINK("https://www.google.com/maps?q=60.132528,-149.433000","map: stored") -> map: stored | S7: (label change) | T7: approve | V7: Military facility, main office in Fort Wainwright, but facility is physically located in Fort Wainwright | W7: JC | X7: 46300
A8: f001585 | B8: 797 | C8: 955 | D8: {BFF9DB9E-CA56-440D-B966-058492E9DF73} | E8: Ketchikan | F8: community_name | G8: 58.37542 | H8: -134.57499 | K8: Ketchikan | L8: Juneau | M8: medium | N8: Independent point (1.0 km from the nearest other-community site); 27 of 27 sites within 15 km are 'Juneau'. Label probably names the operator's home community, not the site. | O8: unchanged | P8: 58.37549 | Q8: -134.57501 | R8: =HYPERLINK("https://www.google.com/maps?q=58.375420,-134.574986","map: stored") -> map: stored | S8: (label change) | T8: reject | U8: Latitude 55.353511° N, Longitude: -131.684099° W | V8: This facility is located in Ketchikan and has the incorrect coordinates. Confirmed via raw CSV file | W8: JC | X8: 46300
A9: f000358 | B9: 898 | C9: 972 | D9: {BACAEA02-40B4-467A-B3B9-39C3197CF50D} | E9: King Cove | F9: community_name | G9: 58.683749 | H9: -156.67213 | K9: King Cove | L9: King Salmon | M9: medium | N9: Independent point (0.1 km from the nearest other-community site); 7 of 7 sites within 15 km are 'King Salmon'. Label probably names the operator's home community, not the site. | O9: unchanged | P9: 58.6839 | Q9: -156.67212 | R9: =HYPERLINK("https://www.google.com/maps?q=58.683749,-156.672126","map: stored") -> map: stored | S9: (label change) | T9: approve | V9: Address is located in King Salmon, verified via satellite imagery | W9: JC | X9: 46300
A10: f001399 | B10: 1858 | C10: 1643 | D10: {EE49D47C-9B92-431B-9D0B-77844BA21CF8} | E10: Stevens Village | F10: community_name | G10: 68.128386 | H10: -145.5355 | K10: Stevens Village | L10: Arctic Village | M10: medium | N10: Independent point (0.1 km from the nearest other-community site); 6 of 6 sites within 15 km are 'Arctic Village'. Label probably names the operator's home community, not the site. | O10: unchanged | P10: 68.12848 | Q10: -145.53552 | R10: =HYPERLINK("https://www.google.com/maps?q=68.128386,-145.535502","map: stored") -> map: stored | S10: (label change) | T10: approve | V10: Confirmed on satellie imagery that it is a school in Arctic Village | W10: JC | X10: 46300

Sheet 5 Copied coords
A1: facility_pid | B1: facility_id | C1: csv_row | D1: GlobalID | E1: label | F1: field | G1: current_lat | H1: current_lon | I1: proposed_lat | J1: proposed_lon | K1: current_value | L1: proposed_value | M1: confidence | N1: evidence | O1: aea_2025_status | P1: aea_2025_map_lat | Q1: aea_2025_map_lon | R1: map: stored | S1: map: proposed | T1: decision | U1: your_value | V1: notes | W1: reviewed_by | X1: reviewed_on
A2: f001469 | B2: 902 | C2: 935 | D2: {835A9532-B50F-4307-8766-44E644F988D9} | E2: Kenai | F2: latitude;longitude | G2: 64.856066 | H2: -147.80275 | I2: 60.58319 | J2: -151.30288 | K2: 64.856066,-147.802751 | L2: 60.58319,-151.30288 | M2: medium | N2: Point duplicates a 'Fairbanks' site within 13 m (copied coordinates); CommunityID agrees with label 'Kenai'. Proposed = medoid of the other 15 'Kenai' sites (community-level precision). | O2: unchanged | P2: 64.85608 | Q2: -147.80261 | R2: =HYPERLINK("https://www.google.com/maps?q=64.856066,-147.802751","map: stored") -> map: stored | S2: =HYPERLINK("https://www.google.com/maps?q=60.583190,-151.302880","map: proposed") -> map: proposed | T2: approve with my value | U2: 60.67854° N, 151.38001° W | V2: The address is noted as 48237 Kenai Spur Hwy, Kenai, AK 99611 on the raw CSV data | W2: JC | X2: 46300
A3: f000292 | B3: 1595 | C3: 1006 | D3: {6D4B4A33-4BA6-4F24-B682-8F598BC19947} | E3: Klawock | F3: latitude;longitude | G3: 66.549243 | H3: -152.63272 | I3: 55.55317 | J3: -133.08533 | K3: 66.54924307,-152.63272144 | L3: 55.55317,-133.08533 | M3: medium | N3: Point duplicates a 'Allakaket' site within 7 m (copied coordinates); CommunityID agrees with label 'Klawock'. Proposed = medoid of the other 7 'Klawock' sites (community-level precision). | O3: unchanged | P3: 66.54932 | Q3: -152.63269 | R3: =HYPERLINK("https://www.google.com/maps?q=66.549243,-152.632721","map: stored") -> map: stored | S3: =HYPERLINK("https://www.google.com/maps?q=55.553170,-133.085330","map: proposed") -> map: proposed | T3: approve with my value | U3: 55.55068° N, -133.09671° W | V3: The facility was confirmed and lat/long was manually found | W3: JC | X3: 46300
A4: f000129 | B4: 1671 | C4: 1218 | D4: {FE1C1D96-F623-4694-ADA9-82D02F405415} | E4: Newtok | F4: latitude;longitude | G4: 59.934137 | H4: -164.03819 | I4: 60.94047 | J4: -164.63101 | K4: 59.93413657,-164.03819378 | L4: 60.94047,-164.63101 | M4: medium | N4: Point duplicates a 'Kipnuk' site within 14 m (copied coordinates); CommunityID agrees with label 'Newtok'. Proposed = medoid of the other 5 'Newtok' sites (community-level precision). | O4: unchanged | P4: 59.93408 | Q4: -164.03821 | R4: =HYPERLINK("https://www.google.com/maps?q=59.934137,-164.038194","map: stored") -> map: stored | S4: =HYPERLINK("https://www.google.com/maps?q=60.940470,-164.631010","map: proposed") -> map: proposed | T4: reject | V4: Newtok was relocated and Kipnuk was evacuated due to Typhoon Halong. This facility can be dropped | W4: JC | X4: 46300
A5: f001579 | B5: 1692 | C5: 1273 | D5: {056D0E34-0F8F-4089-8FD4-38E6687C1E94} | E5: Noorvik | F5: latitude;longitude | G5: 64.322902 | H5: -158.72405 | I5: 66.83375 | J5: -161.039 | K5: 64.32290209,-158.72405346 | L5: 66.83375,-161.039 | M5: medium | N5: Point duplicates a 'Kaltag' site within 28 m (copied coordinates); CommunityID agrees with label 'Noorvik'. Proposed = medoid of the other 8 'Noorvik' sites (community-level precision). | O5: unchanged | P5: 64.32288 | Q5: -158.724 | R5: =HYPERLINK("https://www.google.com/maps?q=64.322902,-158.724053","map: stored") -> map: stored | S5: =HYPERLINK("https://www.google.com/maps?q=66.833750,-161.039000","map: proposed") -> map: proposed | V5: The raw CSV data lists this address "Alaska Village Electric Cooperative 4831 Eagle Street Anchorage, Alaska 99503". It seems like this may be apart of the tank farm, but need to confirm | W5: JC | X5: 46300

Sheet 6 Shared-point stacks
A1: facility_pid | B1: facility_id | C1: csv_row | D1: GlobalID | E1: label | F1: field | G1: current_lat | H1: current_lon | I1: proposed_lat | J1: proposed_lon | K1: current_value | L1: proposed_value | M1: confidence | N1: evidence | O1: aea_2025_status | P1: aea_2025_map_lat | Q1: aea_2025_map_lon | R1: map: stored | S1: map: proposed | T1: decision | U1: your_value | V1: notes | W1: reviewed_by | X1: reviewed_on
A2: f001269 | B2: 1372 | C2: 376 | D2: {5C01B036-AAC1-4876-BF5E-30428802A639} | E2: Chefornak | F2: latitude;longitude | G2: 60.856858 | H2: -162.27653 | I2: 60.15795 | J2: -164.2801 | K2: 60.85685837,-162.27652783 | L2: 60.15795,-164.2801 | M2: medium | N2: Exact point shared with facilities of ['Kipnuk', 'Nightmute', 'Tuntutuliak', 'Tununak']; the build merges the stack into ONE site labelled by the first CSV row (consolidate_facilities). Proposed = medoid of own-label sites. | O2: unchanged | P2: 60.85687 | Q2: -162.27649 | R2: =HYPERLINK("https://www.google.com/maps?q=60.856858,-162.276528","map: stored") -> map: stored | S2: =HYPERLINK("https://www.google.com/maps?q=60.157950,-164.280100","map: proposed") -> map: proposed
A3: f001632 | B3: 1373 | C3: 377 | D3: {DACE43E7-3929-4EAF-A8BD-A30101E62AD1} | E3: Chefornak | F3: latitude;longitude | G3: 60.856858 | H3: -162.27653 | I3: 60.15795 | J3: -164.2801 | K3: 60.85685837,-162.27652783 | L3: 60.15795,-164.2801 | M3: medium | N3: Exact point shared with facilities of ['Kipnuk', 'Nightmute', 'Tuntutuliak', 'Tununak']; the build merges the stack into ONE site labelled by the first CSV row (consolidate_facilities). Proposed = medoid of own-label sites. | O3: removed in 2025 file | R3: =HYPERLINK("https://www.google.com/maps?q=60.856858,-162.276528","map: stored") -> map: stored | S3: =HYPERLINK("https://www.google.com/maps?q=60.157950,-164.280100","map: proposed") -> map: proposed
A4: f001581 | B4: 1375 | C4: 379 | D4: {D87C846D-981B-4E88-AB27-A2DDBF25E98C} | E4: Chefornak | F4: latitude;longitude | G4: 65.97995 | H4: -161.13175 | I4: 60.15795 | J4: -164.2801 | K4: 65.97994995,-161.13175297 | L4: 60.15795,-164.2801 | M4: medium | N4: Exact point shared with facilities of ['Buckland', 'Kongiganak', 'Koyukuk', 'Kwigillingok']; the build merges the stack into ONE site labelled by the first CSV row (consolidate_facilities). Proposed = medoid of own-label sites. | O4: unchanged | P4: 65.97992 | Q4: -161.13177 | R4: =HYPERLINK("https://www.google.com/maps?q=65.979950,-161.131753","map: stored") -> map: stored | S4: =HYPERLINK("https://www.google.com/maps?q=60.157950,-164.280100","map: proposed") -> map: proposed
A5: f001514 | B5: 1385 | C5: 395 | D5: {C558007A-A0AB-4C4D-A836-9CA4EA3BD493} | E5: Chevak | F5: latitude;longitude | G5: 65.332712 | H5: -166.49422 | I5: 61.52809 | J5: -165.5862 | K5: 65.33271165,-166.49422415 | L5: 61.52809,-165.5862 | M5: medium | N5: Exact point shared with facilities of ['Brevig Mission', 'Nightmute', 'Stebbins', 'Toksook Bay', 'Tununak']; the build merges the stack into ONE site labelled by the first CSV row (consolidate_facilities). Proposed = medoid of own-label sites. | O5: unchanged | P5: 65.3327 | Q5: -166.4942 | R5: =HYPERLINK("https://www.google.com/maps?q=65.332712,-166.494224","map: stored") -> map: stored | S5: =HYPERLINK("https://www.google.com/maps?q=61.528090,-165.586200","map: proposed") -> map: proposed
A6: f001486 | B6: 1471 | C6: 684 | D6: {D16B7CA0-CE7A-4D65-864E-5B2599DECFA6} | E6: Galena | F6: latitude;longitude | G6: 66.567962 | H6: -145.25809 | I6: 64.74393 | J6: -156.87661 | K6: 66.56796229,-145.25809 | L6: 64.74393,-156.87661 | M6: medium | N6: Exact point shared with facilities of ['Fort Yukon']; the build merges the stack into ONE site labelled by the first CSV row (consolidate_facilities). Proposed = medoid of own-label sites. | O6: unchanged | P6: 66.56787 | Q6: -145.25812 | R6: =HYPERLINK("https://www.google.com/maps?q=66.567962,-145.258090","map: stored") -> map: stored | S6: =HYPERLINK("https://www.google.com/maps?q=64.743930,-156.876610","map: proposed") -> map: proposed
A7: f000066 | B7: 1475 | C7: 688 | D7: {F0FFCC8F-A5B7-4ADC-8C28-C7FC319FCDDB} | E7: Galena | F7: latitude;longitude | G7: 66.564199 | H7: -145.25764 | I7: 64.74393 | J7: -156.87661 | K7: 66.564199,-145.25763939 | L7: 64.74393,-156.87661 | M7: medium | N7: Exact point shared with facilities of ['Fort Yukon']; the build merges the stack into ONE site labelled by the first CSV row (consolidate_facilities). Proposed = medoid of own-label sites. | O7: unchanged | P7: 66.56427 | Q7: -145.25763 | R7: =HYPERLINK("https://www.google.com/maps?q=66.564199,-145.257639","map: stored") -> map: stored | S7: =HYPERLINK("https://www.google.com/maps?q=64.743930,-156.876610","map: proposed") -> map: proposed
A8: f000216 | B8: 1496 | C8: 754 | D8: {C9AFF599-4CD8-41B4-97E2-04CEFD79683A} | E8: Holy Cross | F8: latitude;longitude | G8: 67.087671 | H8: -157.85672 | I8: 62.19671 | J8: -159.77015 | K8: 67.08767141,-157.85672217 | L8: 62.19671,-159.77015 | M8: medium | N8: Exact point shared with facilities of ['Wales']; the build merges the stack into ONE site labelled by the first CSV row (consolidate_facilities). Proposed = medoid of own-label sites. | O8: unchanged | P8: 67.08771 | Q8: -157.85669 | R8: =HYPERLINK("https://www.google.com/maps?q=67.087671,-157.856722","map: stored") -> map: stored | S8: =HYPERLINK("https://www.google.com/maps?q=62.196710,-159.770150","map: proposed") -> map: proposed
A9: f000650 | B9: 1504 | C9: 786 | D9: {5283F15A-66DA-4487-8444-EC1A2C43934D} | E9: Hooper Bay | F9: latitude;longitude | G9: 64.733919 | H9: -156.91881 | I9: 61.53062 | J9: -166.10234 | K9: 64.73391882,-156.91880943 | L9: 61.53062,-166.10234 | M9: medium | N9: Exact point shared with facilities of ['Galena']; the build merges the stack into ONE site labelled by the first CSV row (consolidate_facilities). Proposed = medoid of own-label sites. | O9: map point corrected Dec 2025 | P9: 61.52991 | Q9: -166.1037 | R9: =HYPERLINK("https://www.google.com/maps?q=64.733919,-156.918809","map: stored") -> map: stored | S9: =HYPERLINK("https://www.google.com/maps?q=61.530620,-166.102340","map: proposed") -> map: proposed
A10: f000329 | B10: 1560 | C10: 891 | D10: {CC2BF2C6-ADA9-481E-9BD6-76C5A72A34F4} | E10: Kaktovik | F10: latitude;longitude | G10: 70.483335 | H10: -157.42604 | I10: 70.12888 | J10: -143.61834 | K10: 70.48333467,-157.42603502 | L10: 70.12888,-143.61834 | M10: medium | N10: Exact point shared with facilities of ['Atqasuk', 'Nuiqsut', 'Point Hope', 'Point Lay']; the build merges the stack into ONE site labelled by the first CSV row (consolidate_facilities). Proposed = medoid of own-label sites. | O10: removed in 2025 file | R10: =HYPERLINK("https://www.google.com/maps?q=70.483335,-157.426035","map: stored") -> map: stored | S10: =HYPERLINK("https://www.google.com/maps?q=70.128880,-143.618340","map: proposed") -> map: proposed
A11: f000058 | B11: 1562 | C11: 893 | D11: {29A9858B-A138-476A-942F-BA787BE7179B} | E11: Kaktovik | F11: latitude;longitude | G11: 70.481532 | H11: -157.42508 | I11: 70.12888 | J11: -143.61834 | K11: 70.48153169,-157.42508015 | L11: 70.12888,-143.61834 | M11: medium | N11: Exact point shared with facilities of ['Atqasuk', 'Nuiqsut']; the build merges the stack into ONE site labelled by the first CSV row (consolidate_facilities). Proposed = medoid of own-label sites. | O11: unchanged | P11: 70.48151 | Q11: -157.42511 | R11: =HYPERLINK("https://www.google.com/maps?q=70.481532,-157.425080","map: stored") -> map: stored | S11: =HYPERLINK("https://www.google.com/maps?q=70.128880,-143.618340","map: proposed") -> map: proposed
A12: f000554 | B12: 1563 | C12: 903 | D12: {4EB90598-665E-44BF-BABD-1D75C638BCF2} | E12: Kaltag | F12: latitude;longitude | G12: 64.87965 | H12: -157.71867 | I12: 64.32472 | J12: -158.72837 | K12: 64.87964972,-157.71866756 | L12: 64.32472,-158.72837 | M12: medium | N12: Exact point shared with facilities of ['Koyukuk']; the build merges the stack into ONE site labelled by the first CSV row (consolidate_facilities). Proposed = medoid of own-label sites. | O12: unchanged | P12: 64.8797 | Q12: -157.71869 | R12: =HYPERLINK("https://www.google.com/maps?q=64.879650,-157.718668","map: stored") -> map: stored | S12: =HYPERLINK("https://www.google.com/maps?q=64.324720,-158.728370","map: proposed") -> map: proposed
A13: f000227 | B13: 1578 | C13: 969 | D13: {E3EF8439-0613-41E1-B9C0-DC105BB3B3C0} | E13: Kiana | F13: latitude;longitude | G13: 65.980507 | H13: -161.13845 | I13: 66.97022 | J13: -160.44308 | K13: 65.98050676,-161.13845313 | L13: 66.97022,-160.44308 | M13: medium | N13: Exact point shared with facilities of ['Selawik']; the build merges the stack into ONE site labelled by the first CSV row (consolidate_facilities). Proposed = medoid of own-label sites. | O13: unchanged | P13: 65.98053 | Q13: -161.13843 | R13: =HYPERLINK("https://www.google.com/maps?q=65.980507,-161.138453","map: stored") -> map: stored | S13: =HYPERLINK("https://www.google.com/maps?q=66.970220,-160.443080","map: proposed") -> map: proposed
A14: f001448 | B14: 1584 | C14: 988 | D14: {72E67206-F008-47E9-AE98-4C85EAD98765} | E14: Kipnuk | F14: latitude;longitude | G14: 60.856858 | H14: -162.27653 | I14: 59.94058 | J14: -164.03627 | K14: 60.85685837,-162.27652783 | L14: 59.94058,-164.03627 | M14: medium | N14: Exact point shared with facilities of ['Chefornak', 'Nightmute', 'Tuntutuliak', 'Tununak']; the build merges the stack into ONE site labelled by the first CSV row (consolidate_facilities). Proposed = medoid of own-label sites. | O14: unchanged | P14: 60.85687 | Q14: -162.27649 | R14: =HYPERLINK("https://www.google.com/maps?q=60.856858,-162.276528","map: stored") -> map: stored | S14: =HYPERLINK("https://www.google.com/maps?q=59.940580,-164.036270","map: proposed") -> map: proposed
A15: f000391 | B15: 1605 | C15: 1052 | D15: {5966569A-E364-492E-AF3E-4EE7DCE3828B} | E15: Kongiganak | F15: latitude;longitude | G15: 65.97995 | H15: -161.13175 | I15: 59.95892 | J15: -162.88771 | K15: 65.97994995,-161.13175297 | L15: 59.95892,-162.88771 | M15: medium | N15: Exact point shared with facilities of ['Buckland', 'Chefornak', 'Koyukuk', 'Kwigillingok']; the build merges the stack into ONE site labelled by the first CSV row (consolidate_facilities). Proposed = medoid of own-label sites. | O15: unchanged | P15: 65.97992 | Q15: -161.13177 | R15: =HYPERLINK("https://www.google.com/maps?q=65.979950,-161.131753","map: stored") -> map: stored | S15: =HYPERLINK("https://www.google.com/maps?q=59.958920,-162.887710","map: proposed") -> map: proposed
A16: f001518 | B16: 1614 | C16: 1081 | D16: {63C660C1-0960-4011-81E0-33F443CB730D} | E16: Koyukuk | F16: latitude;longitude | G16: 65.97995 | H16: -161.13175 | I16: 64.88158 | J16: -157.7057 | K16: 65.97994995,-161.13175297 | L16: 64.88158,-157.7057 | M16: medium | N16: Exact point shared with facilities of ['Buckland', 'Chefornak', 'Kongiganak', 'Kwigillingok']; the build merges the stack into ONE site labelled by the first CSV row (consolidate_facilities). Proposed = medoid of own-label sites. | O16: unchanged | P16: 65.97992 | Q16: -161.13177 | R16: =HYPERLINK("https://www.google.com/maps?q=65.979950,-161.131753","map: stored") -> map: stored | S16: =HYPERLINK("https://www.google.com/maps?q=64.881580,-157.705700","map: proposed") -> map: proposed
A17: f000435 | B17: 1618 | C17: 1095 | D17: {BA9A56A1-5224-45F0-B0DD-070DBFFB2559} | E17: Kwigillingok | F17: latitude;longitude | G17: 65.97995 | H17: -161.13175 | I17: 59.88183 | J17: -163.15163 | K17: 65.97994995,-161.13175297 | L17: 59.88183,-163.15163 | M17: medium | N17: Exact point shared with facilities of ['Buckland', 'Chefornak', 'Kongiganak', 'Koyukuk']; the build merges the stack into ONE site labelled by the first CSV row (consolidate_facilities). Proposed = medoid of own-label sites. | O17: unchanged | P17: 65.97992 | Q17: -161.13177 | R17: =HYPERLINK("https://www.google.com/maps?q=65.979950,-161.131753","map: stored") -> map: stored | S17: =HYPERLINK("https://www.google.com/maps?q=59.881830,-163.151630","map: proposed") -> map: proposed
A18: f000896 | B18: 1630 | C18: 1119 | D18: {3EDD2A9C-65E1-4B69-95C6-B86EF44C2A59} | E18: Lower Kalskag | F18: latitude;longitude | G18: 61.580835 | H18: -159.55105 | I18: 61.51268 | J18: -160.36412 | K18: 61.58083535,-159.55105162 | L18: 61.51268,-160.36412 | M18: medium | N18: Exact point shared with facilities of ['Aniak', 'Chuathbaluk', 'Red Devil', 'Upper Kalskag']; the build merges the stack into ONE site labelled by the first CSV row (consolidate_facilities). Proposed = medoid of own-label sites. | O18: unchanged | P18: 61.57312 | Q18: -159.24902 | R18: =HYPERLINK("https://www.google.com/maps?q=61.580835,-159.551052","map: stored") -> map: stored | S18: =HYPERLINK("https://www.google.com/maps?q=61.512680,-160.364120","map: proposed") -> map: proposed
A19: f000950 | B19: 1654 | C19: 1189 | D19: {E8C7FE98-2833-47DB-A566-8D25750D48D2} | E19: Napakiak | F19: latitude;longitude | G19: 60.81077 | H19: -161.42256 | I19: 60.69617 | J19: -161.98203 | K19: 60.8107704,-161.42255776 | L19: 60.69617,-161.98203 | M19: medium | N19: Exact point shared with facilities of ['Toksook Bay']; the build merges the stack into ONE site labelled by the first CSV row (consolidate_facilities). Proposed = medoid of own-label sites. | O19: unchanged | P19: 60.81091 | Q19: -161.42249 | R19: =HYPERLINK("https://www.google.com/maps?q=60.810770,-161.422558","map: stored") -> map: stored | S19: =HYPERLINK("https://www.google.com/maps?q=60.696170,-161.982030","map: proposed") -> map: proposed
A20: f000627 | B20: 1676 | C20: 1224 | D20: {AE061686-3F3E-4156-A901-5DDB6E3F0237} | E20: Nightmute | F20: latitude;longitude | G20: 60.856858 | H20: -162.27653 | I20: 60.47936 | J20: -164.72564 | K20: 60.85685837,-162.27652783 | L20: 60.47936,-164.72564 | M20: medium | N20: Exact point shared with facilities of ['Chefornak', 'Kipnuk', 'Tuntutuliak', 'Tununak']; the build merges the stack into ONE site labelled by the first CSV row (consolidate_facilities). Proposed = medoid of own-label sites. | O20: unchanged | P20: 60.85687 | Q20: -162.27649 | R20: =HYPERLINK("https://www.google.com/maps?q=60.856858,-162.276528","map: stored") -> map: stored | S20: =HYPERLINK("https://www.google.com/maps?q=60.479360,-164.725640","map: proposed") -> map: proposed
A21: f000764 | B21: 1678 | C21: 1226 | D21: {6EF0C04D-FA10-46F4-A9C4-91EC73504366} | E21: Nightmute | F21: latitude;longitude | G21: 65.332712 | H21: -166.49422 | I21: 60.47936 | J21: -164.72564 | K21: 65.33271165,-166.49422415 | L21: 60.47936,-164.72564 | M21: medium | N21: Exact point shared with facilities of ['Brevig Mission', 'Chevak', 'Stebbins', 'Toksook Bay', 'Tununak']; the build merges the stack into ONE site labelled by the first CSV row (consolidate_facilities). Proposed = medoid of own-label sites. | O21: unchanged | P21: 65.3327 | Q21: -166.4942 | R21: =HYPERLINK("https://www.google.com/maps?q=65.332712,-166.494224","map: stored") -> map: stored | S21: =HYPERLINK("https://www.google.com/maps?q=60.479360,-164.725640","map: proposed") -> map: proposed
A22: f001250 | B22: 1680 | C22: 1228 | D22: {39943186-EB34-4A7C-B510-E1F60F6E5B77} | E22: Nightmute | F22: latitude;longitude | G22: 59.755523 | H22: -154.90217 | I22: 60.47936 | J22: -164.72564 | K22: 59.75552294,-154.90217449 | L22: 60.47936,-164.72564 | M22: medium | N22: Exact point shared with facilities of ['Perryville']; the build merges the stack into ONE site labelled by the first CSV row (consolidate_facilities). Proposed = medoid of own-label sites. | O22: unchanged | P22: 59.75549 | Q22: -154.9021 | R22: =HYPERLINK("https://www.google.com/maps?q=59.755523,-154.902174","map: stored") -> map: stored | S22: =HYPERLINK("https://www.google.com/maps?q=60.479360,-164.725640","map: proposed") -> map: proposed
A23: f001339 | B23: 1693 | C23: 1274 | D23: {41F25397-8168-4A24-BE43-C7E6935BB5AB} | E23: Noorvik | F23: latitude;longitude | G23: 66.971509 | H23: -160.43826 | I23: 66.83375 | J23: -161.039 | K23: 66.97150852,-160.43825735 | L23: 66.83375,-161.039 | M23: medium | N23: Exact point shared with facilities of ['Kiana']; the build merges the stack into ONE site labelled by the first CSV row (consolidate_facilities). Proposed = medoid of own-label sites. | O23: map point corrected Dec 2025 | P23: 66.83289 | Q23: -161.04431 | R23: =HYPERLINK("https://www.google.com/maps?q=66.971509,-160.438257","map: stored") -> map: stored | S23: =HYPERLINK("https://www.google.com/maps?q=66.833750,-161.039000","map: proposed") -> map: proposed
A24: f001746 | B24: 1696 | C24: 1277 | D24: {74D2D10D-C73A-4939-AF83-A4D6FE538506} | E24: Noorvik | F24: latitude;longitude | G24: 66.971509 | H24: -160.43826 | I24: 66.83375 | J24: -161.039 | K24: 66.97150852,-160.43825735 | L24: 66.83375,-161.039 | M24: medium | N24: Exact point shared with facilities of ['Kiana']; the build merges the stack into ONE site labelled by the first CSV row (consolidate_facilities). Proposed = medoid of own-label sites. | O24: removed in 2025 file | R24: =HYPERLINK("https://www.google.com/maps?q=66.971509,-160.438257","map: stored") -> map: stored | S24: =HYPERLINK("https://www.google.com/maps?q=66.833750,-161.039000","map: proposed") -> map: proposed
A25: f001571 | B25: 1716 | C25: 1310 | D25: {32E46B3B-A68A-4AED-A995-44AABFBA609D} | E25: Nuiqsut | F25: latitude;longitude | G25: 70.481532 | H25: -157.42508 | I25: 70.21607 | J25: -150.99798 | K25: 70.48153169,-157.42508015 | L25: 70.21607,-150.99798 | M25: medium | N25: Exact point shared with facilities of ['Atqasuk', 'Kaktovik']; the build merges the stack into ONE site labelled by the first CSV row (consolidate_facilities). Proposed = medoid of own-label sites. | O25: unchanged | P25: 70.48151 | Q25: -157.42511 | R25: =HYPERLINK("https://www.google.com/maps?q=70.481532,-157.425080","map: stored") -> map: stored | S25: =HYPERLINK("https://www.google.com/maps?q=70.216070,-150.997980","map: proposed") -> map: proposed
A26: f000920 | B26: 1717 | C26: 1311 | D26: {F5682527-F6B3-4629-A821-3EEFC8B9A7F1} | E26: Nuiqsut | F26: latitude;longitude | G26: 70.483335 | H26: -157.42604 | I26: 70.21607 | J26: -150.99798 | K26: 70.48333467,-157.42603502 | L26: 70.21607,-150.99798 | M26: medium | N26: Exact point shared with facilities of ['Atqasuk', 'Kaktovik', 'Point Hope', 'Point Lay']; the build merges the stack into ONE site labelled by the first CSV row (consolidate_facilities). Proposed = medoid of own-label sites. | O26: removed in 2025 file | R26: =HYPERLINK("https://www.google.com/maps?q=70.483335,-157.426035","map: stored") -> map: stored | S26: =HYPERLINK("https://www.google.com/maps?q=70.216070,-150.997980","map: proposed") -> map: proposed
A27: f000052 | B27: 1718 | C27: 1312 | D27: {EE035FC2-70D9-42A6-B940-D1F97F642616} | E27: Nuiqsut | F27: latitude;longitude | G27: 70.482405 | H27: -157.42531 | I27: 70.21607 | J27: -150.99798 | K27: 70.48240452,-157.42530546 | L27: 70.21607,-150.99798 | M27: medium | N27: Exact point shared with facilities of ['Atqasuk', 'Point Lay']; the build merges the stack into ONE site labelled by the first CSV row (consolidate_facilities). Proposed = medoid of own-label sites. | O27: unchanged | P27: 70.48248 | Q27: -157.42529 | R27: =HYPERLINK("https://www.google.com/maps?q=70.482405,-157.425305","map: stored") -> map: stored | S27: =HYPERLINK("https://www.google.com/maps?q=70.216070,-150.997980","map: proposed") -> map: proposed
A28: f000632 | B28: 1733 | C28: 1362 | D28: {4533136B-B178-4EEB-8F4E-1BBF21C03ABE} | E28: Perryville | F28: latitude;longitude | G28: 59.755523 | H28: -154.90217 | I28: 55.91043 | J28: -159.14614 | K28: 59.75552294,-154.90217449 | L28: 55.91043,-159.14614 | M28: medium | N28: Exact point shared with facilities of ['Nightmute']; the build merges the stack into ONE site labelled by the first CSV row (consolidate_facilities). Proposed = medoid of own-label sites. | O28: unchanged | P28: 59.75549 | Q28: -154.9021 | R28: =HYPERLINK("https://www.google.com/maps?q=59.755523,-154.902174","map: stored") -> map: stored | S28: =HYPERLINK("https://www.google.com/maps?q=55.910430,-159.146140","map: proposed") -> map: proposed
A29: f000943 | B29: 1752 | C29: 1395 | D29: {7C70AEC7-1C3A-4867-92DF-B24C9EED18CF} | E29: Point Hope | F29: latitude;longitude | G29: 70.483335 | H29: -157.42604 | I29: 68.34952 | J29: -166.73593 | K29: 70.48333467,-157.42603502 | L29: 68.34952,-166.73593 | M29: medium | N29: Exact point shared with facilities of ['Atqasuk', 'Kaktovik', 'Nuiqsut', 'Point Lay']; the build merges the stack into ONE site labelled by the first CSV row (consolidate_facilities). Proposed = medoid of own-label sites. | O29: removed in 2025 file | R29: =HYPERLINK("https://www.google.com/maps?q=70.483335,-157.426035","map: stored") -> map: stored | S29: =HYPERLINK("https://www.google.com/maps?q=68.349520,-166.735930","map: proposed") -> map: proposed
A30: f001019 | B30: 1761 | C30: 1406 | D30: {11C61E2B-C979-4D51-A901-5BDF8ABBF907} | E30: Point Lay | F30: latitude;longitude | G30: 70.129193 | H30: -143.60957 | I30: 69.74182 | J30: -163.01075 | K30: 70.12919302,-143.60957182 | L30: 69.74182,-163.01075 | M30: medium | N30: Exact point shared with facilities of ['Kaktovik']; the build merges the stack into ONE site labelled by the first CSV row (consolidate_facilities). Proposed = medoid of own-label sites. | O30: map point corrected Dec 2025 | P30: 69.74353 | Q30: -163.00189 | R30: =HYPERLINK("https://www.google.com/maps?q=70.129193,-143.609572","map: stored") -> map: stored | S30: =HYPERLINK("https://www.google.com/maps?q=69.741820,-163.010750","map: proposed") -> map: proposed
A31: f001590 | B31: 1762 | C31: 1407 | D31: {678A81B7-2420-44FE-AABF-C45E6E48CC82} | E31: Point Lay | F31: latitude;longitude | G31: 70.482405 | H31: -157.42531 | I31: 69.74182 | J31: -163.01075 | K31: 70.48240452,-157.42530546 | L31: 69.74182,-163.01075 | M31: medium | N31: Exact point shared with facilities of ['Atqasuk', 'Nuiqsut']; the build merges the stack into ONE site labelled by the first CSV row (consolidate_facilities). Proposed = medoid of own-label sites. | O31: unchanged | P31: 70.48248 | Q31: -157.42529 | R31: =HYPERLINK("https://www.google.com/maps?q=70.482405,-157.425305","map: stored") -> map: stored | S31: =HYPERLINK("https://www.google.com/maps?q=69.741820,-163.010750","map: proposed") -> map: proposed
A32: f001076 | B32: 1763 | C32: 1408 | D32: {AC7AE947-7B03-4A9E-ADDF-90A993019617} | E32: Point Lay | F32: latitude;longitude | G32: 70.483335 | H32: -157.42604 | I32: 69.74182 | J32: -163.01075 | K32: 70.48333467,-157.42603502 | L32: 69.74182,-163.01075 | M32: medium | N32: Exact point shared with facilities of ['Atqasuk', 'Kaktovik', 'Nuiqsut', 'Point Hope']; the build merges the stack into ONE site labelled by the first CSV row (consolidate_facilities). Proposed = medoid of own-label sites. | O32: removed in 2025 file | R32: =HYPERLINK("https://www.google.com/maps?q=70.483335,-157.426035","map: stored") -> map: stored | S32: =HYPERLINK("https://www.google.com/maps?q=69.741820,-163.010750","map: proposed") -> map: proposed
A33: f001398 | B33: 1790 | C33: 1461 | D33: {A6656A06-FB6E-44F6-8DEB-0A79C30970C9} | E33: Red Devil | F33: latitude;longitude | G33: 61.580835 | H33: -159.55105 | I33: 61.7825 | J33: -157.33684 | K33: 61.58083535,-159.55105162 | L33: 61.7825,-157.33684 | M33: medium | N33: Exact point shared with facilities of ['Aniak', 'Chuathbaluk', 'Lower Kalskag', 'Upper Kalskag']; the build merges the stack into ONE site labelled by the first CSV row (consolidate_facilities). Proposed = medoid of own-label sites. | O33: unchanged | P33: 61.57312 | Q33: -159.24902 | R33: =HYPERLINK("https://www.google.com/maps?q=61.580835,-159.551052","map: stored") -> map: stored | S33: =HYPERLINK("https://www.google.com/maps?q=61.782500,-157.336840","map: proposed") -> map: proposed
A34: f001572 | B34: 1811 | C34: 1499 | D34: {7A206A94-00D4-4121-BA0A-35593A0FADDC} | E34: Saint Michael | F34: latitude;longitude | G34: 65.332895 | H34: -166.48642 | I34: 63.47875 | J34: -162.03857 | K34: 65.33289523,-166.48642428 | L34: 63.47875,-162.03857 | M34: medium | N34: Exact point shared with facilities of ['Savoonga', 'Teller']; the build merges the stack into ONE site labelled by the first CSV row (consolidate_facilities). Proposed = medoid of own-label sites. | O34: unchanged | P34: 65.33289 | Q34: -166.48639 | R34: =HYPERLINK("https://www.google.com/maps?q=65.332895,-166.486424","map: stored") -> map: stored | S34: =HYPERLINK("https://www.google.com/maps?q=63.478750,-162.038570","map: proposed") -> map: proposed
A35: f000443 | B35: 1812 | C35: 1500 | D35: {E4603DF1-062E-46B4-B972-86EC06249D23} | E35: Saint Michael | F35: latitude;longitude | G35: 65.332895 | H35: -166.48642 | I35: 63.47875 | J35: -162.03857 | K35: 65.33289523,-166.48642428 | L35: 63.47875,-162.03857 | M35: medium | N35: Exact point shared with facilities of ['Savoonga', 'Teller']; the build merges the stack into ONE site labelled by the first CSV row (consolidate_facilities). Proposed = medoid of own-label sites. | O35: removed in 2025 file | R35: =HYPERLINK("https://www.google.com/maps?q=65.332895,-166.486424","map: stored") -> map: stored | S35: =HYPERLINK("https://www.google.com/maps?q=63.478750,-162.038570","map: proposed") -> map: proposed
A36: f000719 | B36: 445 | C36: 1516 | D36: {EF7B6BA1-2FF6-404A-9A5F-01A83B09D969} | E36: Sand Point | F36: latitude;longitude | G36: 53.896944 | H36: -166.54 | I36: 55.34522 | J36: -160.48963 | K36: 53.896944,-166.54 | L36: 55.34522,-160.48963 | M36: medium | N36: Exact point shared with facilities of ['Dutch Harbor']; the build merges the stack into ONE site labelled by the first CSV row (consolidate_facilities). Proposed = medoid of own-label sites. | O36: unchanged | P36: 53.89709 | Q36: -166.53998 | R36: =HYPERLINK("https://www.google.com/maps?q=53.896944,-166.540000","map: stored") -> map: stored | S36: =HYPERLINK("https://www.google.com/maps?q=55.345220,-160.489630","map: proposed") -> map: proposed
A37: f000139 | B37: 1826 | C37: 1527 | D37: {8970B1E0-DE4E-4A98-8A1B-5C858F18F05A} | E37: Savoonga | F37: latitude;longitude | G37: 65.332895 | H37: -166.48642 | I37: 63.69529 | J37: -170.48242 | K37: 65.33289523,-166.48642428 | L37: 63.69529,-170.48242 | M37: medium | N37: Exact point shared with facilities of ['Saint Michael', 'Teller']; the build merges the stack into ONE site labelled by the first CSV row (consolidate_facilities). Proposed = medoid of own-label sites. | O37: unchanged | P37: 65.33289 | Q37: -166.48639 | R37: =HYPERLINK("https://www.google.com/maps?q=65.332895,-166.486424","map: stored") -> map: stored | S37: =HYPERLINK("https://www.google.com/maps?q=63.695290,-170.482420","map: proposed") -> map: proposed
A38: f000832 | B38: 1830 | C38: 1531 | D38: {C8EC9D39-F5C7-4B8E-94A5-4B7BE891EF44} | E38: Savoonga | F38: latitude;longitude | G38: 63.779113 | H38: -171.73406 | I38: 63.69529 | J38: -170.48242 | K38: 63.77911319,-171.73405841 | L38: 63.69529,-170.48242 | M38: medium | N38: Exact point shared with facilities of ['Gambell']; the build merges the stack into ONE site labelled by the first CSV row (consolidate_facilities). Proposed = medoid of own-label sites. | O38: unchanged | P38: 63.77911 | Q38: -171.73401 | R38: =HYPERLINK("https://www.google.com/maps?q=63.779113,-171.734058","map: stored") -> map: stored | S38: =HYPERLINK("https://www.google.com/maps?q=63.695290,-170.482420","map: proposed") -> map: proposed
A39: f001422 | B39: 1834 | C39: 1545 | D39: {2A288E05-E61D-4E46-AE4D-C7D9102802EA} | E39: Selawik | F39: latitude;longitude | G39: 66.973926 | H39: -160.42912 | I39: 66.60506 | J39: -160.01359 | K39: 66.97392587,-160.42911638 | L39: 66.60506,-160.01359 | M39: medium | N39: Exact point shared with facilities of ['Kiana']; the build merges the stack into ONE site labelled by the first CSV row (consolidate_facilities). Proposed = medoid of own-label sites. | O39: unchanged | P39: 66.97388 | Q39: -160.42908 | R39: =HYPERLINK("https://www.google.com/maps?q=66.973926,-160.429116","map: stored") -> map: stored | S39: =HYPERLINK("https://www.google.com/maps?q=66.605060,-160.013590","map: proposed") -> map: proposed
A40: f000090 | B40: 1838 | C40: 1549 | D40: {A5398AFB-3BA8-40B9-8A1A-2886C4335A54} | E40: Selawik | F40: latitude;longitude | G40: 65.980507 | H40: -161.13845 | I40: 66.60506 | J40: -160.01359 | K40: 65.98050676,-161.13845313 | L40: 66.60506,-160.01359 | M40: medium | N40: Exact point shared with facilities of ['Kiana']; the build merges the stack into ONE site labelled by the first CSV row (consolidate_facilities). Proposed = medoid of own-label sites. | O40: unchanged | P40: 65.98053 | Q40: -161.13843 | R40: =HYPERLINK("https://www.google.com/maps?q=65.980507,-161.138453","map: stored") -> map: stored | S40: =HYPERLINK("https://www.google.com/maps?q=66.605060,-160.013590","map: proposed") -> map: proposed
...

Sheet 7 Spelling variants
A1: facility_pid | B1: facility_id | C1: csv_row | D1: GlobalID | E1: label | F1: field | G1: current_lat | H1: current_lon | I1: proposed_lat | J1: proposed_lon | K1: current_value | L1: proposed_value | M1: confidence | N1: evidence | O1: aea_2025_status | P1: aea_2025_map_lat | Q1: aea_2025_map_lon | R1: map: stored | S1: map: proposed | T1: decision | U1: your_value | V1: notes | W1: reviewed_by | X1: reviewed_on
A2: f001783 | B2: 110 | C2: 433 | D2: {60E9F7B5-8A63-4781-81E6-69A693BAD37D} | E2: Clarks Point | F2: community_name | G2: 58.836247 | H2: -158.54447 | K2: Clarks Point | L2: Clark's Point | M2: high | N2: Same CommunityID as 'Clark's Point' ({16FFACBB-CCBD-4A00-829F-F89904105FD5}); the two spellings form separate hub groups in aggregate_hubs (group key is the raw string). | O2: unchanged | P2: 58.8363 | Q2: -158.54449 | R2: =HYPERLINK("https://www.google.com/maps?q=58.836247,-158.544473","map: stored") -> map: stored | S2: (label change) | T2: approve
A3: f001658 | B3: 402 | C3: 434 | D3: {4BEF8811-2274-4D00-AC1C-998D040903CB} | E3: Clarks Point | F3: community_name | G3: 58.8369 | H3: -158.5293 | K3: Clarks Point | L3: Clark's Point | M3: high | N3: Same CommunityID as 'Clark's Point' ({16FFACBB-CCBD-4A00-829F-F89904105FD5}); the two spellings form separate hub groups in aggregate_hubs (group key is the raw string). | O3: unchanged | P3: 58.83691 | Q3: -158.5293 | R3: =HYPERLINK("https://www.google.com/maps?q=58.836900,-158.529300","map: stored") -> map: stored | S3: (label change) | T3: approve
A4: f000037 | B4: 355 | C4: 1483 | D4: {14E28DA5-69A4-4D2F-BB92-286834F0B46F} | E4: Saint Marys | F4: community_name | G4: 62.057547 | H4: -163.29479 | K4: Saint Marys | L4: Saint Mary's | M4: high | N4: Same CommunityID as 'Saint Mary's' ({8AB67F75-EAB7-4DEB-8885-83230D155E9C}); the two spellings form separate hub groups in aggregate_hubs (group key is the raw string). | O4: unchanged | P4: 62.05768 | Q4: -163.2948 | R4: =HYPERLINK("https://www.google.com/maps?q=62.057547,-163.294789","map: stored") -> map: stored | S4: (label change) | T4: approve
A5: f001832 | B5: 763 | C5: 1484 | D5: {E7455FE8-21D1-4DB9-B9A2-3E131F07722C} | E5: Saint Marys | F5: community_name | G5: 62.051516 | H5: -163.17517 | K5: Saint Marys | L5: Saint Mary's | M5: high | N5: Same CommunityID as 'Saint Mary's' ({8AB67F75-EAB7-4DEB-8885-83230D155E9C}); the two spellings form separate hub groups in aggregate_hubs (group key is the raw string). | O5: unchanged | P5: 62.05151 | Q5: -163.17511 | R5: =HYPERLINK("https://www.google.com/maps?q=62.051516,-163.175166","map: stored") -> map: stored | S5: (label change) | T5: approve
A6: f000451 | B6: 939 | C6: 1485 | D6: {FB96C24B-7E2D-41A4-BB41-17A5FC20670F} | E6: Saint Marys | F6: community_name | G6: 62.0519 | H6: -163.17254 | K6: Saint Marys | L6: Saint Mary's | M6: high | N6: Same CommunityID as 'Saint Mary's' ({8AB67F75-EAB7-4DEB-8885-83230D155E9C}); the two spellings form separate hub groups in aggregate_hubs (group key is the raw string). | O6: unchanged | P6: 62.05188 | Q6: -163.17249 | R6: =HYPERLINK("https://www.google.com/maps?q=62.051900,-163.172540","map: stored") -> map: stored | S6: (label change) | T6: approve
A7: f001107 | B7: 1093 | C7: 1486 | D7: {D74EF297-A73B-4181-A759-56C37FDE41DF} | E7: Saint Marys | F7: community_name | G7: 62.06083 | H7: -163.3018 | K7: Saint Marys | L7: Saint Mary's | M7: high | N7: Same CommunityID as 'Saint Mary's' ({8AB67F75-EAB7-4DEB-8885-83230D155E9C}); the two spellings form separate hub groups in aggregate_hubs (group key is the raw string). | O7: unchanged | P7: 62.06091 | Q7: -163.30182 | R7: =HYPERLINK("https://www.google.com/maps?q=62.060830,-163.301800","map: stored") -> map: stored | S7: (label change) | T7: approve
A8: f000726 | B8: 1262 | C8: 1487 | D8: {8AD14672-6D41-4612-9C63-B8526F36290D} | E8: Saint Marys | F8: community_name | G8: 62.052793 | H8: -163.1813 | K8: Saint Marys | L8: Saint Mary's | M8: high | N8: Same CommunityID as 'Saint Mary's' ({8AB67F75-EAB7-4DEB-8885-83230D155E9C}); the two spellings form separate hub groups in aggregate_hubs (group key is the raw string). | O8: unchanged | P8: 62.05292 | Q8: -163.18121 | R8: =HYPERLINK("https://www.google.com/maps?q=62.052793,-163.181297","map: stored") -> map: stored | S8: (label change) | T8: approve
A9: f000266 | B9: 167 | C9: 1480 | D9: {15B249BC-700E-47F6-A75F-F39B21D66AD6} | E9: Saint George Island | F9: community_name | G9: 56.572258 | H9: -169.67107 | K9: Saint George Island | L9: Saint George | M9: high | N9: Same CommunityID as 'Saint George' ({55AFA1A4-5677-44A5-A22C-9F9D370747CE}); the two spellings form separate hub groups in aggregate_hubs (group key is the raw string). | O9: unchanged | P9: 56.57233 | Q9: -169.67108 | R9: =HYPERLINK("https://www.google.com/maps?q=56.572258,-169.671067","map: stored") -> map: stored | S9: (label change) | T9: approve
A10: f000879 | B10: 458 | C10: 1481 | D10: {9F3D036A-E04E-431E-919E-5677FE81308D} | E10: Saint George Island | F10: community_name | G10: 56.577222 | H10: -169.66361 | K10: Saint George Island | L10: Saint George | M10: high | N10: Same CommunityID as 'Saint George' ({55AFA1A4-5677-44A5-A22C-9F9D370747CE}); the two spellings form separate hub groups in aggregate_hubs (group key is the raw string). | O10: unchanged | P10: 56.57727 | Q10: -169.66351 | R10: =HYPERLINK("https://www.google.com/maps?q=56.577222,-169.663611","map: stored") -> map: stored | S10: (label change) | T10: approve
A11: f001280 | B11: 979 | C11: 1482 | D11: {1FF8EE87-BBCC-416D-9B93-4AE5B2704310} | E11: Saint George Island | F11: community_name | G11: 56.602823 | H11: -169.54335 | K11: Saint George Island | L11: Saint George | M11: high | N11: Same CommunityID as 'Saint George' ({55AFA1A4-5677-44A5-A22C-9F9D370747CE}); the two spellings form separate hub groups in aggregate_hubs (group key is the raw string). | O11: unchanged | P11: 56.60291 | Q11: -169.54321 | R11: =HYPERLINK("https://www.google.com/maps?q=56.602823,-169.543351","map: stored") -> map: stored | S11: (label change) | T11: approve
A12: f000057 | B12: 40 | C12: 1509 | D12: {569725C5-F6E9-4B28-96C7-8BDF5BCB6C06} | E12: Saint Paul Island | F12: community_name | G12: 57.150475 | H12: -170.25073 | K12: Saint Paul Island | L12: Saint Paul | M12: high | N12: Same CommunityID as 'Saint Paul' ({B7D914E8-D125-49F0-B374-8AE610E5DBC7}); the two spellings form separate hub groups in aggregate_hubs (group key is the raw string). | O12: unchanged | P12: 57.15051 | Q12: -170.25061 | R12: =HYPERLINK("https://www.google.com/maps?q=57.150475,-170.250733","map: stored") -> map: stored | S12: (label change) | T12: approve
A13: f000464 | B13: 35 | C13: 1510 | D13: {66E08F69-68FD-40AD-99B3-7A2007C0697D} | E13: Saint Paul Island | F13: community_name | G13: 57.15813 | H13: -170.22983 | K13: Saint Paul Island | L13: Saint Paul | M13: high | N13: Same CommunityID as 'Saint Paul' ({B7D914E8-D125-49F0-B374-8AE610E5DBC7}); the two spellings form separate hub groups in aggregate_hubs (group key is the raw string). | O13: unchanged | P13: 57.15808 | Q13: -170.2298 | R13: =HYPERLINK("https://www.google.com/maps?q=57.158130,-170.229828","map: stored") -> map: stored | S13: (label change) | T13: approve
